[2023-01-31T16:00:00.570+0000] {taskinstance.py:1083} INFO - Dependencies all met for <TaskInstance: flights_data.mirror_countries scheduled__2023-01-31T15:00:00+00:00 [queued]>
[2023-01-31T16:00:00.576+0000] {taskinstance.py:1083} INFO - Dependencies all met for <TaskInstance: flights_data.mirror_countries scheduled__2023-01-31T15:00:00+00:00 [queued]>
[2023-01-31T16:00:00.577+0000] {taskinstance.py:1279} INFO - 
--------------------------------------------------------------------------------
[2023-01-31T16:00:00.577+0000] {taskinstance.py:1280} INFO - Starting attempt 1 of 1
[2023-01-31T16:00:00.578+0000] {taskinstance.py:1281} INFO - 
--------------------------------------------------------------------------------
[2023-01-31T16:00:00.585+0000] {taskinstance.py:1300} INFO - Executing <Task(PythonOperator): mirror_countries> on 2023-01-31 15:00:00+00:00
[2023-01-31T16:00:00.591+0000] {standard_task_runner.py:55} INFO - Started process 4612 to run task
[2023-01-31T16:00:00.594+0000] {standard_task_runner.py:82} INFO - Running: ['***', 'tasks', 'run', 'flights_data', 'mirror_countries', 'scheduled__2023-01-31T15:00:00+00:00', '--job-id', '132', '--raw', '--subdir', 'DAGS_FOLDER/flights_dag.py', '--cfg-path', '/tmp/tmp64uz4_9q']
[2023-01-31T16:00:00.595+0000] {standard_task_runner.py:83} INFO - Job 132: Subtask mirror_countries
[2023-01-31T16:00:00.647+0000] {task_command.py:388} INFO - Running <TaskInstance: flights_data.mirror_countries scheduled__2023-01-31T15:00:00+00:00 [running]> on host 91e4c7304a05
[2023-01-31T16:00:00.696+0000] {taskinstance.py:1509} INFO - Exporting the following env vars:
AIRFLOW_CTX_DAG_OWNER=***
AIRFLOW_CTX_DAG_ID=flights_data
AIRFLOW_CTX_TASK_ID=mirror_countries
AIRFLOW_CTX_EXECUTION_DATE=2023-01-31T15:00:00+00:00
AIRFLOW_CTX_TRY_NUMBER=1
AIRFLOW_CTX_DAG_RUN_ID=scheduled__2023-01-31T15:00:00+00:00
[2023-01-31T16:00:01.496+0000] {taskinstance.py:1768} ERROR - Task failed with exception
Traceback (most recent call last):
  File "/home/airflow/.local/lib/python3.7/site-packages/sqlalchemy/engine/base.py", line 3361, in _wrap_pool_connect
    return fn()
  File "/home/airflow/.local/lib/python3.7/site-packages/sqlalchemy/pool/base.py", line 327, in connect
    return _ConnectionFairy._checkout(self)
  File "/home/airflow/.local/lib/python3.7/site-packages/sqlalchemy/pool/base.py", line 894, in _checkout
    fairy = _ConnectionRecord.checkout(pool)
  File "/home/airflow/.local/lib/python3.7/site-packages/sqlalchemy/pool/base.py", line 493, in checkout
    rec = pool._do_get()
  File "/home/airflow/.local/lib/python3.7/site-packages/sqlalchemy/pool/impl.py", line 146, in _do_get
    self._dec_overflow()
  File "/home/airflow/.local/lib/python3.7/site-packages/sqlalchemy/util/langhelpers.py", line 72, in __exit__
    with_traceback=exc_tb,
  File "/home/airflow/.local/lib/python3.7/site-packages/sqlalchemy/util/compat.py", line 211, in raise_
    raise exception
  File "/home/airflow/.local/lib/python3.7/site-packages/sqlalchemy/pool/impl.py", line 143, in _do_get
    return self._create_connection()
  File "/home/airflow/.local/lib/python3.7/site-packages/sqlalchemy/pool/base.py", line 273, in _create_connection
    return _ConnectionRecord(self)
  File "/home/airflow/.local/lib/python3.7/site-packages/sqlalchemy/pool/base.py", line 388, in __init__
    self.__connect()
  File "/home/airflow/.local/lib/python3.7/site-packages/sqlalchemy/pool/base.py", line 691, in __connect
    pool.logger.debug("Error on connect(): %s", e)
  File "/home/airflow/.local/lib/python3.7/site-packages/sqlalchemy/util/langhelpers.py", line 72, in __exit__
    with_traceback=exc_tb,
  File "/home/airflow/.local/lib/python3.7/site-packages/sqlalchemy/util/compat.py", line 211, in raise_
    raise exception
  File "/home/airflow/.local/lib/python3.7/site-packages/sqlalchemy/pool/base.py", line 686, in __connect
    self.dbapi_connection = connection = pool._invoke_creator(self)
  File "/home/airflow/.local/lib/python3.7/site-packages/sqlalchemy/engine/create.py", line 578, in connect
    return dialect.connect(*cargs, **cparams)
  File "/home/airflow/.local/lib/python3.7/site-packages/sqlalchemy/engine/default.py", line 598, in connect
    return self.dbapi.connect(*cargs, **cparams)
  File "/home/airflow/.local/lib/python3.7/site-packages/psycopg2/__init__.py", line 122, in connect
    conn = _connect(dsn, connection_factory=connection_factory, **kwasync)
psycopg2.OperationalError: could not translate host name "use your own public ip address" to address: Name or service not known


The above exception was the direct cause of the following exception:

Traceback (most recent call last):
  File "/home/airflow/.local/lib/python3.7/site-packages/airflow/operators/python.py", line 175, in execute
    return_value = self.execute_callable()
  File "/home/airflow/.local/lib/python3.7/site-packages/airflow/operators/python.py", line 192, in execute_callable
    return self.python_callable(*self.op_args, **self.op_kwargs)
  File "/opt/airflow/dags/flights_dag.py", line 28, in get_countries
    df.to_sql('mrr_countries', connect_to_db(),if_exists='replace')
  File "/home/airflow/.local/lib/python3.7/site-packages/pandas/core/generic.py", line 2882, in to_sql
    method=method,
  File "/home/airflow/.local/lib/python3.7/site-packages/pandas/io/sql.py", line 728, in to_sql
    **engine_kwargs,
  File "/home/airflow/.local/lib/python3.7/site-packages/pandas/io/sql.py", line 1758, in to_sql
    dtype=dtype,
  File "/home/airflow/.local/lib/python3.7/site-packages/pandas/io/sql.py", line 1650, in prep_table
    table.create()
  File "/home/airflow/.local/lib/python3.7/site-packages/pandas/io/sql.py", line 856, in create
    if self.exists():
  File "/home/airflow/.local/lib/python3.7/site-packages/pandas/io/sql.py", line 840, in exists
    return self.pd_sql.has_table(self.name, self.schema)
  File "/home/airflow/.local/lib/python3.7/site-packages/pandas/io/sql.py", line 1783, in has_table
    insp = sa.inspect(self.connectable)
  File "/home/airflow/.local/lib/python3.7/site-packages/sqlalchemy/inspection.py", line 64, in inspect
    ret = reg(subject)
  File "/home/airflow/.local/lib/python3.7/site-packages/sqlalchemy/engine/reflection.py", line 182, in _engine_insp
    return Inspector._construct(Inspector._init_engine, bind)
  File "/home/airflow/.local/lib/python3.7/site-packages/sqlalchemy/engine/reflection.py", line 117, in _construct
    init(self, bind)
  File "/home/airflow/.local/lib/python3.7/site-packages/sqlalchemy/engine/reflection.py", line 128, in _init_engine
    engine.connect().close()
  File "/home/airflow/.local/lib/python3.7/site-packages/sqlalchemy/engine/base.py", line 3315, in connect
    return self._connection_cls(self, close_with_result=close_with_result)
  File "/home/airflow/.local/lib/python3.7/site-packages/sqlalchemy/engine/base.py", line 96, in __init__
    else engine.raw_connection()
  File "/home/airflow/.local/lib/python3.7/site-packages/sqlalchemy/engine/base.py", line 3394, in raw_connection
    return self._wrap_pool_connect(self.pool.connect, _connection)
  File "/home/airflow/.local/lib/python3.7/site-packages/sqlalchemy/engine/base.py", line 3365, in _wrap_pool_connect
    e, dialect, self
  File "/home/airflow/.local/lib/python3.7/site-packages/sqlalchemy/engine/base.py", line 2199, in _handle_dbapi_exception_noconnection
    sqlalchemy_exception, with_traceback=exc_info[2], from_=e
  File "/home/airflow/.local/lib/python3.7/site-packages/sqlalchemy/util/compat.py", line 211, in raise_
    raise exception
  File "/home/airflow/.local/lib/python3.7/site-packages/sqlalchemy/engine/base.py", line 3361, in _wrap_pool_connect
    return fn()
  File "/home/airflow/.local/lib/python3.7/site-packages/sqlalchemy/pool/base.py", line 327, in connect
    return _ConnectionFairy._checkout(self)
  File "/home/airflow/.local/lib/python3.7/site-packages/sqlalchemy/pool/base.py", line 894, in _checkout
    fairy = _ConnectionRecord.checkout(pool)
  File "/home/airflow/.local/lib/python3.7/site-packages/sqlalchemy/pool/base.py", line 493, in checkout
    rec = pool._do_get()
  File "/home/airflow/.local/lib/python3.7/site-packages/sqlalchemy/pool/impl.py", line 146, in _do_get
    self._dec_overflow()
  File "/home/airflow/.local/lib/python3.7/site-packages/sqlalchemy/util/langhelpers.py", line 72, in __exit__
    with_traceback=exc_tb,
  File "/home/airflow/.local/lib/python3.7/site-packages/sqlalchemy/util/compat.py", line 211, in raise_
    raise exception
  File "/home/airflow/.local/lib/python3.7/site-packages/sqlalchemy/pool/impl.py", line 143, in _do_get
    return self._create_connection()
  File "/home/airflow/.local/lib/python3.7/site-packages/sqlalchemy/pool/base.py", line 273, in _create_connection
    return _ConnectionRecord(self)
  File "/home/airflow/.local/lib/python3.7/site-packages/sqlalchemy/pool/base.py", line 388, in __init__
    self.__connect()
  File "/home/airflow/.local/lib/python3.7/site-packages/sqlalchemy/pool/base.py", line 691, in __connect
    pool.logger.debug("Error on connect(): %s", e)
  File "/home/airflow/.local/lib/python3.7/site-packages/sqlalchemy/util/langhelpers.py", line 72, in __exit__
    with_traceback=exc_tb,
  File "/home/airflow/.local/lib/python3.7/site-packages/sqlalchemy/util/compat.py", line 211, in raise_
    raise exception
  File "/home/airflow/.local/lib/python3.7/site-packages/sqlalchemy/pool/base.py", line 686, in __connect
    self.dbapi_connection = connection = pool._invoke_creator(self)
  File "/home/airflow/.local/lib/python3.7/site-packages/sqlalchemy/engine/create.py", line 578, in connect
    return dialect.connect(*cargs, **cparams)
  File "/home/airflow/.local/lib/python3.7/site-packages/sqlalchemy/engine/default.py", line 598, in connect
    return self.dbapi.connect(*cargs, **cparams)
  File "/home/airflow/.local/lib/python3.7/site-packages/psycopg2/__init__.py", line 122, in connect
    conn = _connect(dsn, connection_factory=connection_factory, **kwasync)
sqlalchemy.exc.OperationalError: (psycopg2.OperationalError) could not translate host name "use your own public ip address" to address: Name or service not known

(Background on this error at: https://sqlalche.me/e/14/e3q8)
[2023-01-31T16:00:01.508+0000] {taskinstance.py:1323} INFO - Marking task as FAILED. dag_id=flights_data, task_id=mirror_countries, execution_date=20230131T150000, start_date=20230131T160000, end_date=20230131T160001
[2023-01-31T16:00:01.516+0000] {standard_task_runner.py:105} ERROR - Failed to execute job 132 for task mirror_countries ((psycopg2.OperationalError) could not translate host name "use your own public ip address" to address: Name or service not known

(Background on this error at: https://sqlalche.me/e/14/e3q8); 4612)
[2023-01-31T16:00:01.546+0000] {local_task_job.py:208} INFO - Task exited with return code 1
[2023-01-31T16:00:01.560+0000] {taskinstance.py:2578} INFO - 0 downstream tasks scheduled from follow-on schedule check
