[2023-01-29T12:05:50.984+0000] {taskinstance.py:1083} INFO - Dependencies all met for <TaskInstance: simple_dag.waiting_for_data scheduled__2023-01-28T00:00:00+00:00 [queued]>
[2023-01-29T12:05:50.990+0000] {taskinstance.py:1083} INFO - Dependencies all met for <TaskInstance: simple_dag.waiting_for_data scheduled__2023-01-28T00:00:00+00:00 [queued]>
[2023-01-29T12:05:50.990+0000] {taskinstance.py:1279} INFO - 
--------------------------------------------------------------------------------
[2023-01-29T12:05:50.991+0000] {taskinstance.py:1280} INFO - Starting attempt 2 of 6
[2023-01-29T12:05:50.991+0000] {taskinstance.py:1281} INFO - 
--------------------------------------------------------------------------------
[2023-01-29T12:05:51.000+0000] {taskinstance.py:1300} INFO - Executing <Task(FileSensor): waiting_for_data> on 2023-01-28 00:00:00+00:00
[2023-01-29T12:05:51.004+0000] {standard_task_runner.py:55} INFO - Started process 1177 to run task
[2023-01-29T12:05:51.008+0000] {standard_task_runner.py:82} INFO - Running: ['***', 'tasks', 'run', 'simple_dag', 'waiting_for_data', 'scheduled__2023-01-28T00:00:00+00:00', '--job-id', '7', '--raw', '--subdir', 'DAGS_FOLDER/simple_dag.py', '--cfg-path', '/tmp/tmpf8j9qjxt']
[2023-01-29T12:05:51.008+0000] {standard_task_runner.py:83} INFO - Job 7: Subtask waiting_for_data
[2023-01-29T12:05:51.059+0000] {task_command.py:388} INFO - Running <TaskInstance: simple_dag.waiting_for_data scheduled__2023-01-28T00:00:00+00:00 [running]> on host 5df8d992093e
[2023-01-29T12:05:51.106+0000] {taskinstance.py:1509} INFO - Exporting the following env vars:
AIRFLOW_CTX_DAG_OWNER=***
AIRFLOW_CTX_DAG_ID=simple_dag
AIRFLOW_CTX_TASK_ID=waiting_for_data
AIRFLOW_CTX_EXECUTION_DATE=2023-01-28T00:00:00+00:00
AIRFLOW_CTX_TRY_NUMBER=2
AIRFLOW_CTX_DAG_RUN_ID=scheduled__2023-01-28T00:00:00+00:00
[2023-01-29T12:05:51.122+0000] {taskinstance.py:1768} ERROR - Task failed with exception
Traceback (most recent call last):
  File "/home/airflow/.local/lib/python3.7/site-packages/airflow/sensors/base.py", line 199, in execute
    poke_return = self.poke(context)
  File "/home/airflow/.local/lib/python3.7/site-packages/airflow/sensors/filesystem.py", line 61, in poke
    hook = FSHook(self.fs_conn_id)
  File "/home/airflow/.local/lib/python3.7/site-packages/airflow/hooks/filesystem.py", line 38, in __init__
    conn = self.get_connection(conn_id)
  File "/home/airflow/.local/lib/python3.7/site-packages/airflow/hooks/base.py", line 72, in get_connection
    conn = Connection.get_connection_from_secrets(conn_id)
  File "/home/airflow/.local/lib/python3.7/site-packages/airflow/models/connection.py", line 435, in get_connection_from_secrets
    raise AirflowNotFoundException(f"The conn_id `{conn_id}` isn't defined")
airflow.exceptions.AirflowNotFoundException: The conn_id `fs-default` isn't defined
[2023-01-29T12:05:51.125+0000] {taskinstance.py:1323} INFO - Marking task as UP_FOR_RETRY. dag_id=simple_dag, task_id=waiting_for_data, execution_date=20230128T000000, start_date=20230129T120550, end_date=20230129T120551
[2023-01-29T12:05:51.132+0000] {standard_task_runner.py:105} ERROR - Failed to execute job 7 for task waiting_for_data (The conn_id `fs-default` isn't defined; 1177)
[2023-01-29T12:05:51.181+0000] {local_task_job.py:208} INFO - Task exited with return code 1
[2023-01-29T12:05:51.195+0000] {taskinstance.py:2578} INFO - 0 downstream tasks scheduled from follow-on schedule check
